Workbook

Sheet npr_unprocessed
B1: gene_name | C1: X | D1: threshold | E1: ADA | F1: ADE | G1: ADF | H1: ADL | I1: AFD | J1: AIA | K1: AIB | L1: AIM | M1: AIN | N1: AIY | O1: AIZ | P1: ALA | Q1: ALM | R1: ALN | S1: AQR | T1: AS | U1: ASEL | V1: ASER | W1: ASG | X1: ASH | Y1: ASI | Z1: ASJ | AA1: ASK | AB1: AUA | AC1: AVA | AD1: AVB | AE1: AVD | AF1: AVE | AG1: AVF | AH1: AVG | AI1: AVH | AJ1: AVJ | AK1: AVK | AL1: AVL | AM1: AVM | AN1: AWA | AO1: AWB | AP1: AWCL | AQ1: AWCR | AR1: BAG | AS1: BDU | AT1: CAN | AU1: CEP | AV1: DA | AW1: DA09 | AX1: DB | AY1: DB01 | AZ1: DVA | BA1: DVB | BB1: DVC | BC1: FLP | BD1: HSN | BE1: I1 | BF1: I2 | BG1: I3 | BH1: I4 | BI1: I5 | BJ1: I6 | BK1: IL1 | BL1: IL2D | BM1: IL2V | BN1: IL2L | BO1: IL2R | BP1: LUA | BQ1: M1 | BR1: M2 | BS1: M3 | BT1: M4 | BU1: M5 | BV1: MC | BW1: MI | BX1: NSM | BY1: OLL | BZ1: OLQ | CA1: PDA | CB1: PDB | CC1: PDE | CD1: PHA | CE1: PHB | CF1: PHC | CG1: PLM | CH1: PLN | CI1: PQR | CJ1: PVC | CK1: PVD | CL1: PVM | CM1: PVN | CN1: PVP | CO1: PVQ | CP1: PVR | CQ1: PVT | CR1: PVW | CS1: RIA | CT1: RIB | CU1: RIC | CV1: RID | CW1: RIF | CX1: RIG | CY1: RIH | CZ1: RIM | DA1: RIP | DB1: RIR | DC1: RIS | DD1: RIV | DE1: RMDD | DF1: RMDV | DG1: RMDL | DH1: RMDR | DI1: RMED | DJ1: RMEV | DK1: RMEL | DL1: RMER | DM1: RMF | DN1: RMG | DO1: RMH | DP1: SAA | DQ1: SAB | DR1: SDQ | DS1: SIA | DT1: SIB | DU1: SMB | DV1: SMD | DW1: URA | DX1: URB | DY1: URX | DZ1: URY | EA1: VA | EB1: VA12 | EC1: VB | ED1: VB01 | EE1: VB02 | EF1: VC | EG1: VC_4_5 | EH1: VD | EI1: DD
A2: 72003 | B2: acc-1 | C2: WBGene00010275 | D2: 4 | E2: 0 | F2: 0 | G2: 0 | H2: 0 | I2: 0 | J2: 0 | K2: 499.51274 | L2: 0 | M2: 0 | N2: 0 | O2: 0 | P2: 0 | Q2: 0 | R2: 0 | S2: 0 | T2: 0 | U2: 0 | V2: 0 | W2: 0 | X2: 0 | Y2: 0 | Z2: 0 | AA2: 0 | AB2: 0 | AC2: 0 | AD2: 0 | AE2: 0 | AF2: 0 | AG2: 0 | AH2: 0 | AI2: 0 | AJ2: 0 | AK2: 0 | AL2: 0 | AM2: 0 | AN2: 0 | AO2: 0 | AP2: 0 | AQ2: 0 | AR2: 0 | AS2: 0 | AT2: 0 | AU2: 0 | AV2: 152.05183 | AW2: 120.57642 | AX2: 161.39316 | AY2: 211.59339 | AZ2: 0 | BA2: 0 | BB2: 0 | BC2: 0 | BD2: 0 | BE2: 0 | BF2: 0 | BG2: 0 | BH2: 0 | BI2: 0 | BJ2: 233.79073 | BK2: 0 | BL2: 0 | BM2: 0 | BN2: 0 | BO2: 0 | BP2: 0 | BQ2: 0 | BR2: 0 | BS2: 767.92736 | BT2: 0 | BU2: 0 | BV2: 253.21426 | BW2: 344.72331 | BX2: 0 | BY2: 0 | BZ2: 0 | CA2: 0 | CB2: 0 | CC2: 0 | CD2: 0 | CE2: 0 | CF2: 0 | CG2: 151.25166 | CH2: 0 | CI2: 0 | CJ2: 0 | CK2: 0 | CL2: 0 | CM2: 0 | CN2: 0 | CO2: 0 | CP2: 0 | CQ2: 0 | CR2: 0 | CS2: 0 | CT2: 0 | CU2: 0 | CV2: 0 | CW2: 0 | CX2: 0 | CY2: 0 | CZ2: 0 | DA2: 0 | DB2: 0 | DC2: 0 | DD2: 0 | DE2: 572.44767 | DF2: 572.44767 | DG2: 515.78259 | DH2: 515.78259 | DI2: 0 | DJ2: 0 | DK2: 0 | DL2: 0 | DM2: 0 | DN2: 0 | DO2: 0 | DP2: 497.69068 | DQ2: 0 | DR2: 0 | DS2: 0 | DT2: 0 | DU2: 0 | DV2: 1033.916 | DW2: 0 | DX2: 0 | DY2: 0 | DZ2: 0 | EA2: 0 | EB2: 0 | EC2: 0 | ED2: 0 | EE2: 0 | EF2: 0 | EG2: 0 | EH2: 0 | EI2: 0
A3: 74263 | B3: acc-2 | C3: WBGene00008280 | D3: 4 | E3: 0 | F3: 0 | G3: 0 | H3: 0 | I3: 0 | J3: 0 | K3: 0 | L3: 145.43339 | M3: 0 | N3: 0 | O3: 403.65377 | P3: 0 | Q3: 0 | R3: 0 | S3: 0 | T3: 0 | U3: 0 | V3: 0 | W3: 0 | X3: 0 | Y3: 0 | Z3: 0 | AA3: 0 | AB3: 0 | AC3: 0 | AD3: 0 | AE3: 0 | AF3: 0 | AG3: 0 | AH3: 0 | AI3: 0 | AJ3: 0 | AK3: 0 | AL3: 0 | AM3: 0 | AN3: 0 | AO3: 0 | AP3: 0 | AQ3: 0 | AR3: 0 | AS3: 0 | AT3: 0 | AU3: 0 | AV3: 0 | AW3: 0 | AX3: 0 | AY3: 0 | AZ3: 0 | BA3: 0 | BB3: 0 | BC3: 0 | BD3: 0 | BE3: 0 | BF3: 0 | BG3: 0 | BH3: 0 | BI3: 0 | BJ3: 0 | BK3: 0 | BL3: 0 | BM3: 0 | BN3: 147.11187 | BO3: 147.11187 | BP3: 0 | BQ3: 0 | BR3: 0 | BS3: 0 | BT3: 0 | BU3: 0 | BV3: 0 | BW3: 0 | BX3: 0 | BY3: 0 | BZ3: 0 | CA3: 0 | CB3: 0 | CC3: 0 | CD3: 0 | CE3: 0 | CF3: 0 | CG3: 0 | CH3: 0 | CI3: 0 | CJ3: 0 | CK3: 0 | CL3: 0 | CM3: 0 | CN3: 0 | CO3: 0 | CP3: 0 | CQ3: 0 | CR3: 0 | CS3: 197.41516 | CT3: 0 | CU3: 0 | CV3: 0 | CW3: 0 | CX3: 650.92824 | CY3: 0 | CZ3: 0 | DA3: 0 | DB3: 0 | DC3: 0 | DD3: 0 | DE3: 0 | DF3: 0 | DG3: 0 | DH3: 0 | DI3: 0 | DJ3: 0 | DK3: 0 | DL3: 0 | DM3: 0 | DN3: 0 | DO3: 0 | DP3: 0 | DQ3: 0 | DR3: 0 | DS3: 0 | DT3: 0 | DU3: 0 | DV3: 0 | DW3: 0 | DX3: 0 | DY3: 60.911119 | DZ3: 0 | EA3: 0 | EB3: 0 | EC3: 0 | ED3: 0 | EE3: 0 | EF3: 0 | EG3: 0 | EH3: 0 | EI3: 0
A4: 36123 | B4: acc-3 | C4: WBGene00018880 | D4: 4 | E4: 0 | F4: 0 | G4: 56.797527 | H4: 0 | I4: 0 | J4: 0 | K4: 0 | L4: 0 | M4: 0 | N4: 0 | O4: 0 | P4: 245.28431 | Q4: 0 | R4: 0 | S4: 0 | T4: 0 | U4: 0 | V4: 0 | W4: 0 | X4: 0 | Y4: 0 | Z4: 0 | AA4: 0 | AB4: 0 | AC4: 0 | AD4: 0 | AE4: 0 | AF4: 0 | AG4: 0 | AH4: 0 | AI4: 0 | AJ4: 0 | AK4: 0 | AL4: 0 | AM4: 0 | AN4: 0 | AO4: 0 | AP4: 0 | AQ4: 0 | AR4: 0 | AS4: 0 | AT4: 0 | AU4: 0 | AV4: 0 | AW4: 0 | AX4: 0 | AY4: 0 | AZ4: 0 | BA4: 0 | BB4: 122.34567 | BC4: 0 | BD4: 0 | BE4: 0 | BF4: 0 | BG4: 0 | BH4: 0 | BI4: 0 | BJ4: 0 | BK4: 0 | BL4: 0 | BM4: 0 | BN4: 0 | BO4: 0 | BP4: 0 | BQ4: 0 | BR4: 0 | BS4: 0 | BT4: 0 | BU4: 0 | BV4: 0 | BW4: 0 | BX4: 0 | BY4: 0 | BZ4: 0 | CA4: 0 | CB4: 0 | CC4: 0 | CD4: 0 | CE4: 0 | CF4: 0 | CG4: 0 | CH4: 0 | CI4: 0 | CJ4: 0 | CK4: 0 | CL4: 0 | CM4: 0 | CN4: 0 | CO4: 0 | CP4: 0 | CQ4: 0 | CR4: 0 | CS4: 0 | CT4: 0 | CU4: 0 | CV4: 0 | CW4: 0 | CX4: 0 | CY4: 0 | CZ4: 49.169911 | DA4: 0 | DB4: 0 | DC4: 0 | DD4: 0 | DE4: 0 | DF4: 0 | DG4: 0 | DH4: 0 | DI4: 132.85601 | DJ4: 132.85601 | DK4: 0 | DL4: 0 | DM4: 0 | DN4: 0 | DO4: 0 | DP4: 0 | DQ4: 0 | DR4: 0 | DS4: 0 | DT4: 0 | DU4: 0 | DV4: 0 | DW4: 0 | DX4: 0 | DY4: 0 | DZ4: 0 | EA4: 0 | EB4: 0 | EC4: 0 | ED4: 0 | EE4: 0 | EF4: 0 | EG4: 0 | EH4: 0 | EI4: 0
A5: 69823 | B5: acc-4 | C5: WBGene00012099 | D5: 4 | E5: 0 | F5: 0 | G5: 0 | H5: 0 | I5: 0 | J5: 147.13259 | K5: 0 | L5: 0 | M5: 0 | N5: 0 | O5: 0 | P5: 0 | Q5: 0 | R5: 0 | S5: 0 | T5: 185.77027 | U5: 0 | V5: 0 | W5: 0 | X5: 0 | Y5: 0 | Z5: 0 | AA5: 0 | AB5: 0 | AC5: 58.626273 | AD5: 0 | AE5: 108.13149 | AF5: 0 | AG5: 0 | AH5: 0 | AI5: 0 | AJ5: 0 | AK5: 0 | AL5: 0 | AM5: 0 | AN5: 0 | AO5: 0 | AP5: 0 | AQ5: 0 | AR5: 0 | AS5: 0 | AT5: 0 | AU5: 0 | AV5: 366.21423 | AW5: 43.690939 | AX5: 311.77236 | AY5: 172.54317 | AZ5: 0 | BA5: 0 | BB5: 0 | BC5: 0 | BD5: 62.170001 | BE5: 0 | BF5: 0 | BG5: 0 | BH5: 0 | BI5: 0 | BJ5: 0 | BK5: 0 | BL5: 288.87891 | BM5: 288.87891 | BN5: 152.86433 | BO5: 152.86433 | BP5: 0 | BQ5: 34.75437 | BR5: 0 | BS5: 0 | BT5: 58.561724 | BU5: 0 | BV5: 0 | BW5: 0 | BX5: 0 | BY5: 0 | BZ5: 0 | CA5: 0 | CB5: 110.48105 | CC5: 0 | CD5: 0 | CE5: 0 | CF5: 0 | CG5: 0 | CH5: 54.584356 | CI5: 0 | CJ5: 117.64664 | CK5: 0 | CL5: 0 | CM5: 0 | CN5: 0 | CO5: 0 | CP5: 0 | CQ5: 0 | CR5: 0 | CS5: 0 | CT5: 0 | CU5: 0 | CV5: 26.98537 | CW5: 114.91591 | CX5: 0 | CY5: 156.18315 | CZ5: 0 | DA5: 67.069665 | DB5: 0 | DC5: 0 | DD5: 0 | DE5: 0 | DF5: 0 | DG5: 0 | DH5: 0 | DI5: 0 | DJ5: 0 | DK5: 0 | DL5: 0 | DM5: 0 | DN5: 0 | DO5: 0 | DP5: 0 | DQ5: 606.15063 | DR5: 0 | DS5: 74.867279 | DT5: 159.83955 | DU5: 45.21979 | DV5: 0 | DW5: 195.27448 | DX5: 216.37115 | DY5: 42.739211 | DZ5: 0 | EA5: 166.01004 | EB5: 247.17876 | EC5: 139.25852 | ED5: 118.24523 | EE5: 92.408268 | EF5: 0 | EG5: 0 | EH5: 0 | EI5: 0
A6: 621813 | B6: acr-10 | C6: WBGene00000049 | D6: 4 | E6: 0 | F6: 0 | G6: 0 | H6: 0 | I6: 0 | J6: 0 | K6: 0 | L6: 0 | M6: 0 | N6: 0 | O6: 0 | P6: 0 | Q6: 0 | R6: 0 | S6: 0 | T6: 0 | U6: 0 | V6: 0 | W6: 0 | X6: 0 | Y6: 0 | Z6: 0 | AA6: 0 | AB6: 0 | AC6: 0 | AD6: 0 | AE6: 0 | AF6: 0 | AG6: 0 | AH6: 0 | AI6: 0 | AJ6: 0 | AK6: 0 | AL6: 0 | AM6: 0 | AN6: 0 | AO6: 0 | AP6: 0 | AQ6: 0 | AR6: 0 | AS6: 0 | AT6: 0 | AU6: 0 | AV6: 0 | AW6: 0 | AX6: 0 | AY6: 0 | AZ6: 0 | BA6: 0 | BB6: 0 | BC6: 0 | BD6: 0 | BE6: 0 | BF6: 0 | BG6: 0 | BH6: 0 | BI6: 0 | BJ6: 0 | BK6: 0 | BL6: 0 | BM6: 0 | BN6: 0 | BO6: 0 | BP6: 0 | BQ6: 0 | BR6: 0 | BS6: 0 | BT6: 0 | BU6: 0 | BV6: 0 | BW6: 0 | BX6: 0 | BY6: 0 | BZ6: 0 | CA6: 0 | CB6: 0 | CC6: 0 | CD6: 0 | CE6: 0 | CF6: 0 | CG6: 0 | CH6: 0 | CI6: 0 | CJ6: 0 | CK6: 0 | CL6: 0 | CM6: 0 | CN6: 0 | CO6: 0 | CP6: 0 | CQ6: 0 | CR6: 0 | CS6: 0 | CT6: 0 | CU6: 0 | CV6: 0 | CW6: 0 | CX6: 0 | CY6: 0 | CZ6: 0 | DA6: 0 | DB6: 0 | DC6: 0 | DD6: 0 | DE6: 0 | DF6: 0 | DG6: 0 | DH6: 0 | DI6: 0 | DJ6: 0 | DK6: 0 | DL6: 0 | DM6: 0 | DN6: 0 | DO6: 0 | DP6: 0 | DQ6: 0 | DR6: 0 | DS6: 0 | DT6: 0 | DU6: 0 | DV6: 0 | DW6: 0 | DX6: 0 | DY6: 0 | DZ6: 0 | EA6: 0 | EB6: 0 | EC6: 0 | ED6: 0 | EE6: 0 | EF6: 0 | EG6: 0 | EH6: 0 | EI6: 0
A7: 93515 | B7: acr-11 | C7: WBGene00000050 | D7: 4 | E7: 179.06191 | F7: 0 | G7: 0 | H7: 0 | I7: 0 | J7: 0 | K7: 0 | L7: 0 | M7: 0 | N7: 0 | O7: 0 | P7: 0 | Q7: 0 | R7: 0 | S7: 0 | T7: 0 | U7: 0 | V7: 0 | W7: 0 | X7: 0 | Y7: 0 | Z7: 0 | AA7: 0 | AB7: 0 | AC7: 0 | AD7: 0 | AE7: 0 | AF7: 0 | AG7: 0 | AH7: 0 | AI7: 0 | AJ7: 0 | AK7: 0 | AL7: 0 | AM7: 0 | AN7: 0 | AO7: 0 | AP7: 0 | AQ7: 0 | AR7: 0 | AS7: 0 | AT7: 0 | AU7: 0 | AV7: 0 | AW7: 0 | AX7: 0 | AY7: 0 | AZ7: 0 | BA7: 0 | BB7: 0 | BC7: 0 | BD7: 0 | BE7: 0 | BF7: 0 | BG7: 0 | BH7: 0 | BI7: 0 | BJ7: 0 | BK7: 0 | BL7: 0 | BM7: 0 | BN7: 0 | BO7: 0 | BP7: 0 | BQ7: 0 | BR7: 0 | BS7: 0 | BT7: 0 | BU7: 0 | BV7: 0 | BW7: 0 | BX7: 0 | BY7: 0 | BZ7: 0 | CA7: 0 | CB7: 0 | CC7: 0 | CD7: 0 | CE7: 0 | CF7: 0 | CG7: 0 | CH7: 0 | CI7: 0 | CJ7: 0 | CK7: 0 | CL7: 0 | CM7: 0 | CN7: 0 | CO7: 0 | CP7: 0 | CQ7: 0 | CR7: 0 | CS7: 0 | CT7: 0 | CU7: 0 | CV7: 0 | CW7: 0 | CX7: 0 | CY7: 0 | CZ7: 0 | DA7: 0 | DB7: 0 | DC7: 0 | DD7: 0 | DE7: 0 | DF7: 0 | DG7: 0 | DH7: 0 | DI7: 0 | DJ7: 0 | DK7: 0 | DL7: 0 | DM7: 0 | DN7: 0 | DO7: 0 | DP7: 0 | DQ7: 0 | DR7: 0 | DS7: 0 | DT7: 0 | DU7: 0 | DV7: 0 | DW7: 0 | DX7: 389.24914 | DY7: 0 | DZ7: 0 | EA7: 0 | EB7: 0 | EC7: 0 | ED7: 0 | EE7: 0 | EF7: 0 | EG7: 0 | EH7: 0 | EI7: 0
A8: 20973 | B8: acr-12 | C8: WBGene00000051 | D8: 4 | E8: 0 | F8: 127.58076 | G8: 0 | H8: 0 | I8: 0 | J8: 0 | K8: 0 | L8: 0 | M8: 0 | N8: 65.1342 | O8: 73.733305 | P8: 0 | Q8: 132.48155 | R8: 0 | S8: 0 | T8: 211.06658 | U8: 0 | V8: 0 | W8: 0 | X8: 0 | Y8: 0 | Z8: 0 | AA8: 0 | AB8: 118.1078 | AC8: 0 | AD8: 86.90268 | AE8: 208.82288 | AF8: 0 | AG8: 0 | AH8: 168.11014 | AI8: 176.07393 | AJ8: 176.74829 | AK8: 44.565153 | AL8: 77.059764 | AM8: 154.4664 | AN8: 0 | AO8: 0 | AP8: 0 | AQ8: 0 | AR8: 0 | AS8: 0 | AT8: 0 | AU8: 0 | AV8: 263.84451 | AW8: 318.54694 | AX8: 359.85492 | AY8: 304.53206 | AZ8: 0 | BA8: 415.53111 | BB8: 0 | BC8: 0 | BD8: 94.201605 | BE8: 153.52632 | BF8: 0 | BG8: 0 | BH8: 203.79069 | BI8: 84.532877 | BJ8: 0 | BK8: 392.35211 | BL8: 74.994796 | BM8: 74.994796 | BN8: 51.984892 | BO8: 51.984892 | BP8: 0 | BQ8: 0 | BR8: 133.81521 | BS8: 0 | BT8: 110.12938 | BU8: 185.44626 | BV8: 0 | BW8: 0 | BX8: 370.92102 | BY8: 154.66008 | BZ8: 0 | CA8: 195.39326 | CB8: 239.94847 | CC8: 136.64595 | CD8: 0 | CE8: 0 | CF8: 0 | CG8: 152.95283 | CH8: 334.2856 | CI8: 0 | CJ8: 131.48305 | CK8: 0 | CL8: 160.6267 | CM8: 0 | CN8: 0 | CO8: 0 | CP8: 190.23714 | CQ8: 33.674922 | CR8: 215.11486 | CS8: 0 | CT8: 0 | CU8: 0 | CV8: 91.669035 | CW8: 0 | CX8: 621.10153 | CY8: 0 | CZ8: 106.11612 | DA8: 0 | DB8: 0 | DC8: 49.833327 | DD8: 0 | DE8: 300.08453 | DF8: 300.08453 | DG8: 247.42171 | DH8: 247.42171 | DI8: 0 | DJ8: 0 | DK8: 0 | DL8: 0 | DM8: 148.24151 | DN8: 0 | DO8: 0 | DP8: 229.12056 | DQ8: 259.05968 | DR8: 0 | DS8: 0 | DT8: 337.93671 | DU8: 177.99493 | DV8: 162.76947 | DW8: 237.9652 | DX8: 0 | DY8: 0 | DZ8: 0 | EA8: 268.16749 | EB8: 337.03676 | EC8: 245.42905 | ED8: 147.99039 | EE8: 198.29811 | EF8: 145.07891 | EG8: 0 | EH8: 373.96325 | EI8: 373.96325
A9: 96894 | B9: acr-14 | C9: WBGene00000053 | D9: 4 | E9: 0 | F9: 0 | G9: 0 | H9: 0 | I9: 0 | J9: 0 | K9: 0 | L9: 0 | M9: 0 | N9: 0 | O9: 0 | P9: 0 | Q9: 0 | R9: 0 | S9: 0 | T9: 635.1066 | U9: 0 | V9: 0 | W9: 0 | X9: 0 | Y9: 0 | Z9: 0 | AA9: 0 | AB9: 0 | AC9: 238.655 | AD9: 0 | AE9: 66.72539 | AF9: 102.0883 | AG9: 0 | AH9: 0 | AI9: 0 | AJ9: 117.554 | AK9: 0 | AL9: 0 | AM9: 0 | AN9: 0 | AO9: 0 | AP9: 0 | AQ9: 0 | AR9: 0 | AS9: 0 | AT9: 0 | AU9: 0 | AV9: 272.023 | AW9: 186.3107 | AX9: 0 | AY9: 0 | AZ9: 0 | BA9: 0 | BB9: 0 | BC9: 0 | BD9: 0 | BE9: 0 | BF9: 0 | BG9: 0 | BH9: 0 | BI9: 0 | BJ9: 0 | BK9: 0 | BL9: 0 | BM9: 0 | BN9: 0 | BO9: 0 | BP9: 0 | BQ9: 0 | BR9: 77.31867 | BS9: 0 | BT9: 0 | BU9: 0 | BV9: 0 | BW9: 0 | BX9: 0 | BY9: 0 | BZ9: 0 | CA9: 31.70557 | CB9: 138.7398 | CC9: 0 | CD9: 0 | CE9: 0 | CF9: 0 | CG9: 0 | CH9: 0 | CI9: 0 | CJ9: 0 | CK9: 0 | CL9: 0 | CM9: 97.47588 | CN9: 69.82698 | CO9: 0 | CP9: 0 | CQ9: 0 | CR9: 0 | CS9: 0 | CT9: 0 | CU9: 0 | CV9: 0 | CW9: 242.3272 | CX9: 0 | CY9: 0 | CZ9: 0 | DA9: 0 | DB9: 0 | DC9: 0 | DD9: 0 | DE9: 0 | DF9: 0 | DG9: 0 | DH9: 0 | DI9: 0 | DJ9: 0 | DK9: 0 | DL9: 0 | DM9: 0 | DN9: 0 | DO9: 0 | DP9: 0 | DQ9: 690.6101 | DR9: 0 | DS9: 0 | DT9: 0 | DU9: 0 | DV9: 0 | DW9: 0 | DX9: 0 | DY9: 0 | DZ9: 0 | EA9: 214.359 | EB9: 77.80382 | EC9: 0 | ED9: 0 | EE9: 0 | EF9: 0 | EG9: 0 | EH9: 234.8403 | EI9: 234.8403
A10: 110143 | B10: acr-15 | C10: WBGene00000054 | D10: 4 | E10: 0 | F10: 0 | G10: 0 | H10: 0 | I10: 0 | J10: 0 | K10: 0 | L10: 0 | M10: 0 | N10: 0 | O10: 0 | P10: 0 | Q10: 0 | R10: 0 | S10: 0 | T10: 0 | U10: 0 | V10: 0 | W10: 0 | X10: 0 | Y10: 0 | Z10: 0 | AA10: 0 | AB10: 0 | AC10: 464.6646 | AD10: 163.858 | AE10: 0 | AF10: 0 | AG10: 0 | AH10: 1855.875 | AI10: 0 | AJ10: 0 | AK10: 0 | AL10: 0 | AM10: 0 | AN10: 0 | AO10: 0 | AP10: 0 | AQ10: 0 | AR10: 0 | AS10: 0 | AT10: 0 | AU10: 0 | AV10: 0 | AW10: 0 | AX10: 80.41611 | AY10: 0 | AZ10: 0 | BA10: 0 | BB10: 0 | BC10: 0 | BD10: 0 | BE10: 0 | BF10: 0 | BG10: 0 | BH10: 0 | BI10: 80.36757 | BJ10: 0 | BK10: 0 | BL10: 0 | BM10: 0 | BN10: 0 | BO10: 0 | BP10: 0 | BQ10: 0 | BR10: 0 | BS10: 116.1899 | BT10: 0 | BU10: 0 | BV10: 0 | BW10: 0 | BX10: 0 | BY10: 0 | BZ10: 0 | CA10: 0 | CB10: 142.1305 | CC10: 0 | CD10: 0 | CE10: 0 | CF10: 0 | CG10: 0 | CH10: 0 | CI10: 0 | CJ10: 0 | CK10: 0 | CL10: 0 | CM10: 0 | CN10: 0 | CO10: 0 | CP10: 0 | CQ10: 0 | CR10: 0 | CS10: 0 | CT10: 0 | CU10: 0 | CV10: 0 | CW10: 0 | CX10: 0 | CY10: 0 | CZ10: 0 | DA10: 333.9144 | DB10: 0 | DC10: 0 | DD10: 0 | DE10: 0 | DF10: 0 | DG10: 0 | DH10: 0 | DI10: 0 | DJ10: 0 | DK10: 0 | DL10: 0 | DM10: 0 | DN10: 0 | DO10: 0 | DP10: 0 | DQ10: 0 | DR10: 0 | DS10: 0 | DT10: 0 | DU10: 0 | DV10: 0 | DW10: 0 | DX10: 0 | DY10: 0 | DZ10: 0 | EA10: 0 | EB10: 179.5448 | EC10: 0 | ED10: 0 | EE10: 0 | EF10: 0 | EG10: 0 | EH10: 0 | EI10: 0
A11: 110154 | B11: acr-16 | C11: WBGene00000055 | D11: 4 | E11: 0 | F11: 0 | G11: 0 | H11: 0 | I11: 0 | J11: 0 | K11: 0 | L11: 0 | M11: 0 | N11: 0 | O11: 0 | P11: 0 | Q11: 0 | R11: 0 | S11: 0 | T11: 0 | U11: 0 | V11: 0 | W11: 0 | X11: 0 | Y11: 0 | Z11: 0 | AA11: 0 | AB11: 0 | AC11: 559.2597 | AD11: 57.64416 | AE11: 0 | AF11: 0 | AG11: 0 | AH11: 0 | AI11: 0 | AJ11: 0 | AK11: 0 | AL11: 0 | AM11: 0 | AN11: 0 | AO11: 0 | AP11: 0 | AQ11: 0 | AR11: 0 | AS11: 0 | AT11: 0 | AU11: 0 | AV11: 0 | AW11: 0 | AX11: 107.9895 | AY11: 0 | AZ11: 0 | BA11: 0 | BB11: 0 | BC11: 0 | BD11: 0 | BE11: 0 | BF11: 0 | BG11: 0 | BH11: 0 | BI11: 0 | BJ11: 0 | BK11: 0 | BL11: 0 | BM11: 0 | BN11: 0 | BO11: 0 | BP11: 0 | BQ11: 0 | BR11: 0 | BS11: 0 | BT11: 40.61079 | BU11: 0 | BV11: 0 | BW11: 0 | BX11: 0 | BY11: 0 | BZ11: 0 | CA11: 0 | CB11: 0 | CC11: 0 | CD11: 0 | CE11: 0 | CF11: 0 | CG11: 0 | CH11: 0 | CI11: 0 | CJ11: 0 | CK11: 0 | CL11: 0 | CM11: 0 | CN11: 0 | CO11: 0 | CP11: 140.2037 | CQ11: 0 | CR11: 0 | CS11: 0 | CT11: 133.1087 | CU11: 0 | CV11: 0 | CW11: 0 | CX11: 0 | CY11: 0 | CZ11: 0 | DA11: 0 | DB11: 0 | DC11: 0 | DD11: 0 | DE11: 0 | DF11: 0 | DG11: 0 | DH11: 0 | DI11: 0 | DJ11: 0 | DK11: 0 | DL11: 0 | DM11: 0 | DN11: 0 | DO11: 0 | DP11: 0 | DQ11: 0 | DR11: 0 | DS11: 0 | DT11: 0 | DU11: 0 | DV11: 48.59814 | DW11: 0 | DX11: 0 | DY11: 0 | DZ11: 0 | EA11: 0 | EB11: 0 | EC11: 0 | ED11: 0 | EE11: 0 | EF11: 0 | EG11: 0 | EH11: 0 | EI11: 0
A12: 43106 | B12: acr-17 | C12: WBGene00000056 | D12: 4 | E12: 0 | F12: 0 | G12: 46.959361 | H12: 0 | I12: 0 | J12: 0 | K12: 0 | L12: 0 | M12: 0 | N12: 0 | O12: 0 | P12: 0 | Q12: 0 | R12: 0 | S12: 0 | T12: 0 | U12: 0 | V12: 0 | W12: 18.134812 | X12: 0 | Y12: 0 | Z12: 0 | AA12: 0 | AB12: 0 | AC12: 0 | AD12: 0 | AE12: 0 | AF12: 0 | AG12: 0 | AH12: 0 | AI12: 0 | AJ12: 0 | AK12: 0 | AL12: 0 | AM12: 0 | AN12: 0 | AO12: 0 | AP12: 0 | AQ12: 0 | AR12: 0 | AS12: 0 | AT12: 0 | AU12: 0 | AV12: 72.176558 | AW12: 0 | AX12: 264.54744 | AY12: 0 | AZ12: 0 | BA12: 21.440576 | BB12: 0 | BC12: 0 | BD12: 39.015068 | BE12: 0 | BF12: 0 | BG12: 0 | BH12: 0 | BI12: 0 | BJ12: 0 | BK12: 0 | BL12: 0 | BM12: 0 | BN12: 0 | BO12: 0 | BP12: 0 | BQ12: 50.931921 | BR12: 0 | BS12: 304.23544 | BT12: 0 | BU12: 0 | BV12: 0 | BW12: 40.9102 | BX12: 0 | BY12: 0 | BZ12: 0 | CA12: 0 | CB12: 0 | CC12: 0 | CD12: 0 | CE12: 0 | CF12: 0 | CG12: 0 | CH12: 0 | CI12: 0 | CJ12: 0 | CK12: 93.329778 | CL12: 0 | CM12: 0 | CN12: 0 | CO12: 0 | CP12: 0 | CQ12: 0 | CR12: 0 | CS12: 0 | CT12: 0 | CU12: 0 | CV12: 0 | CW12: 0 | CX12: 106.83283 | CY12: 222.20887 | CZ12: 0 | DA12: 174.64218 | DB12: 0 | DC12: 0 | DD12: 0 | DE12: 0 | DF12: 0 | DG12: 0 | DH12: 0 | DI12: 0 | DJ12: 0 | DK12: 0 | DL12: 0 | DM12: 0 | DN12: 0 | DO12: 0 | DP12: 0 | DQ12: 0 | DR12: 0 | DS12: 0 | DT12: 0 | DU12: 0 | DV12: 0 | DW12: 0 | DX12: 0 | DY12: 0 | DZ12: 0 | EA12: 0 | EB12: 0 | EC12: 0 | ED12: 0 | EE12: 0 | EF12: 0 | EG12: 0 | EH12: 0 | EI12: 0
A13: 110243 | B13: acr-18 | C13: WBGene00000057 | D13: 4 | E13: 0 | F13: 0 | G13: 0 | H13: 0 | I13: 0 | J13: 0 | K13: 0 | L13: 0 | M13: 0 | N13: 0 | O13: 0 | P13: 0 | Q13: 0 | R13: 0 | S13: 0 | T13: 0 | U13: 0 | V13: 0 | W13: 0 | X13: 0 | Y13: 0 | Z13: 0 | AA13: 0 | AB13: 0 | AC13: 64.51307 | AD13: 0 | AE13: 0 | AF13: 46.35229 | AG13: 0 | AH13: 0 | AI13: 0 | AJ13: 0 | AK13: 0 | AL13: 0 | AM13: 0 | AN13: 0 | AO13: 0 | AP13: 0 | AQ13: 0 | AR13: 0 | AS13: 0 | AT13: 0 | AU13: 0 | AV13: 0 | AW13: 18.83916 | AX13: 0 | AY13: 0 | AZ13: 12.87447 | BA13: 0 | BB13: 0 | BC13: 0 | BD13: 0 | BE13: 0 | BF13: 0 | BG13: 0 | BH13: 0 | BI13: 0 | BJ13: 0 | BK13: 0 | BL13: 0 | BM13: 0 | BN13: 0 | BO13: 0 | BP13: 0 | BQ13: 194.4053 | BR13: 0 | BS13: 0 | BT13: 0 | BU13: 0 | BV13: 0 | BW13: 0 | BX13: 0 | BY13: 0 | BZ13: 0 | CA13: 0 | CB13: 79.16407 | CC13: 0 | CD13: 0 | CE13: 0 | CF13: 0 | CG13: 0 | CH13: 0 | CI13: 0 | CJ13: 0 | CK13: 0 | CL13: 0 | CM13: 0 | CN13: 0 | CO13: 0 | CP13: 0 | CQ13: 0 | CR13: 0 | CS13: 0 | CT13: 0 | CU13: 0 | CV13: 0 | CW13: 0 | CX13: 0 | CY13: 0 | CZ13: 0 | DA13: 0 | DB13: 0 | DC13: 0 | DD13: 0 | DE13: 0 | DF13: 0 | DG13: 0 | DH13: 0 | DI13: 0 | DJ13: 0 | DK13: 0 | DL13: 0 | DM13: 0 | DN13: 0 | DO13: 0 | DP13: 0 | DQ13: 0 | DR13: 0 | DS13: 73.58072 | DT13: 0 | DU13: 0 | DV13: 137.0989 | DW13: 65.16263 | DX13: 0 | DY13: 0 | DZ13: 0 | EA13: 0 | EB13: 0 | EC13: 0 | ED13: 80.48283 | EE13: 0 | EF13: 0 | EG13: 0 | EH13: 0 | EI13: 0
... A170: 75453 | B170: unc-63 | C170: WBGene00006797 | D170: 4 | E170: 0 | F170: 0 | G170: 0 | H170: 0 | I170: 0 | J170: 0 | K170: 0 | L170: 15.76522 | M170: 0 | N170: 0 | O170: 9.7793576 | P170: 0 | Q170: 7.9700725 | R170: 0 | S170: 0 | T170: 32.186825 | U170: 0 | V170: 0 | W170: 0 | X170: 0 | Y170: 0 | Z170: 0 | AA170: 0 | AB170: 0 | AC170: 0 | AD170: 0 | AE170: 26.305403 | AF170: 0 | AG170: 0 | AH170: 28.860345 | AI170: 0 | AJ170: 0 | AK170: 0 | AL170: 0 | AM170: 9.9612709 | AN170: 0 | AO170: 0 | AP170: 0 | AQ170: 0 | AR170: 0 | AS170: 0 | AT170: 0 | AU170: 0 | AV170: 77.902833 | AW170: 47.851265 | AX170: 59.654846 | AY170: 41.100561 | AZ170: 0 | BA170: 63.36227 | BB170: 0 | BC170: 0 | BD170: 25.312997 | BE170: 19.085234 | BF170: 0 | BG170: 0 | BH170: 29.802728 | BI170: 8.206225 | BJ170: 0 | BK170: 45.74003 | BL170: 16.367543 | BM170: 16.367543 | BN170: 21.92407 | BO170: 21.92407 | BP170: 0 | BQ170: 0 | BR170: 24.599113 | BS170: 29.183579 | BT170: 0 | BU170: 0 | BV170: 0 | BW170: 10.60229 | BX170: 39.082208 | BY170: 0 | BZ170: 0 | CA170: 45.642642 | CB170: 45.884365 | CC170: 26.716409 | CD170: 0 | CE170: 0 | CF170: 0 | CG170: 14.198096 | CH170: 0 | CI170: 0 | CJ170: 17.024021 | CK170: 0 | CL170: 59.315839 | CM170: 0 | CN170: 0 | CO170: 0 | CP170: 19.209114 | CQ170: 0 | CR170: 10.569187 | CS170: 0 | CT170: 0 | CU170: 0 | CV170: 0 | CW170: 0 | CX170: 0 | CY170: 0 | CZ170: 0 | DA170: 0 | DB170: 0 | DC170: 0 | DD170: 0 | DE170: 0 | DF170: 0 | DG170: 0 | DH170: 0 | DI170: 0 | DJ170: 0 | DK170: 0 | DL170: 0 | DM170: 0 | DN170: 0 | DO170: 0 | DP170: 0 | DQ170: 0 | DR170: 0 | DS170: 0 | DT170: 0 | DU170: 26.695057 | DV170: 25.075787 | DW170: 36.814691 | DX170: 37.56893 | DY170: 0 | DZ170: 0 | EA170: 26.387907 | EB170: 12.082236 | EC170: 34.949328 | ED170: 35.702428 | EE170: 20.922131 | EF170: 0 | EG170: 0 | EH170: 0 | EI170: 0

Sheet npr_formulas
A1: gene_name | B1: X | C1: ADA | D1: ADE | E1: ADF | F1: ADL | G1: AFD | H1: AIA | I1: AIB | J1: AIM | K1: AIN | L1: AIY | M1: AIZ | N1: ALA | O1: ALM | P1: ALN | Q1: AQR | R1: AS | S1: ASEL | T1: ASER | U1: ASG | V1: ASH | W1: ASI | X1: ASJ | Y1: ASK | Z1: AUA | AA1: AVA | AB1: AVB | AC1: AVD | AD1: AVE | AE1: AVF | AF1: AVG | AG1: AVH | AH1: AVJ | AI1: AVK | AJ1: AVL | AK1: AVM | AL1: AWA | AM1: AWB | AN1: AWCL | AO1: AWCR | AP1: BAG | AQ1: BDU | AR1: CAN | AS1: CEP | AT1: DA | AU1: DA09 | AV1: DB | AW1: DB01 | AX1: DVA | AY1: DVB | AZ1: DVC | BA1: FLP | BB1: HSN | BC1: I1 | BD1: I2 | BE1: I3 | BF1: I4 | BG1: I5 | BH1: I6 | BI1: IL1 | BJ1: IL2D | BK1: IL2V | BL1: IL2L | BM1: IL2R | BN1: LUA | BO1: M1 | BP1: M2 | BQ1: M3 | BR1: M4 | BS1: M5 | BT1: MC | BU1: MI | BV1: NSM | BW1: OLL | BX1: OLQ | BY1: PDA | BZ1: PDB | CA1: PDE | CB1: PHA | CC1: PHB | CD1: PHC | CE1: PLM | CF1: PLN | CG1: PQR | CH1: PVC | CI1: PVD | CJ1: PVM | CK1: PVN | CL1: PVP | CM1: PVQ | CN1: PVR | CO1: PVT | CP1: PVW | CQ1: RIA | CR1: RIB | CS1: RIC | CT1: RID | CU1: RIF | CV1: RIG | CW1: RIH | CX1: RIM | CY1: RIP | CZ1: RIR | DA1: RIS | DB1: RIV | DC1: RMDD | DD1: RMDV | DE1: RMDL | DF1: RMDR | DG1: RMED | DH1: RMEV | DI1: RMEL | DJ1: RMER | DK1: RMF | DL1: RMG | DM1: RMH | DN1: SAA | DO1: SAB | DP1: SDQ | DQ1: SIA | DR1: SIB | DS1: SMB | DT1: SMD | DU1: URA | DV1: URB | DW1: URX | DX1: URY | DY1: VA | DZ1: VA12 | EA1: VB | EB1: VB01 | EC1: VB02 | ED1: VC | EE1: VC_4_5 | EF1: VD | EG1: DD
A2: acc-1 | B2: WBGene00010275 | C2: =npr_unprocessed!E2>0 -> FALSE | D2: =npr_unprocessed!F2>0 -> FALSE | E2: =npr_unprocessed!G2>0 -> FALSE | F2: =npr_unprocessed!H2>0 -> FALSE | G2: =npr_unprocessed!I2>0 -> FALSE | H2: =npr_unprocessed!J2>0 -> FALSE | I2: =npr_unprocessed!K2>0 -> TRUE | J2: =npr_unprocessed!L2>0 -> FALSE | ... EG2: =npr_unprocessed!EI2>0 -> FALSE
A3: acc-2 | B3: WBGene00008280 | C3: =npr_unprocessed!E3>0 -> FALSE | D3: =npr_unprocessed!F3>0 -> FALSE | E3: =npr_unprocessed!G3>0 -> FALSE | F3: =npr_unprocessed!H3>0 -> FALSE | G3: =npr_unprocessed!I3>0 -> FALSE | H3: =npr_unprocessed!J3>0 -> FALSE | I3: =npr_unprocessed!K3>0 -> FALSE | J3: =npr_unprocessed!L3>0 -> TRUE | ... EG3: =npr_unprocessed!EI3>0 -> FALSE
A4: acc-3 | B4: WBGene00018880 | C4: =npr_unprocessed!E4>0 -> FALSE | D4: =npr_unprocessed!F4>0 -> FALSE | E4: =npr_unprocessed!G4>0 -> TRUE | F4: =npr_unprocessed!H4>0 -> FALSE | G4: =npr_unprocessed!I4>0 -> FALSE | H4: =npr_unprocessed!J4>0 -> FALSE | I4: =npr_unprocessed!K4>0 -> FALSE | J4: =npr_unprocessed!L4>0 -> FALSE | ... EG4: =npr_unprocessed!EI4>0 -> FALSE
A5: acc-4 | B5: WBGene00012099 | C5: =npr_unprocessed!E5>0 -> FALSE | D5: =npr_unprocessed!F5>0 -> FALSE | E5: =npr_unprocessed!G5>0 -> FALSE | F5: =npr_unprocessed!H5>0 -> FALSE | G5: =npr_unprocessed!I5>0 -> FALSE | H5: =npr_unprocessed!J5>0 -> TRUE | I5: =npr_unprocessed!K5>0 -> FALSE | J5: =npr_unprocessed!L5>0 -> FALSE | ... EG5: =npr_unprocessed!EI5>0 -> FALSE
A6: acr-10 | B6: WBGene00000049 | C6: =npr_unprocessed!E6>0 -> FALSE | D6: =npr_unprocessed!F6>0 -> FALSE | E6: =npr_unprocessed!G6>0 -> FALSE | F6: =npr_unprocessed!H6>0 -> FALSE | G6: =npr_unprocessed!I6>0 -> FALSE | H6: =npr_unprocessed!J6>0 -> FALSE | I6: =npr_unprocessed!K6>0 -> FALSE | J6: =npr_unprocessed!L6>0 -> FALSE | ... EG6: =npr_unprocessed!EI6>0 -> FALSE
A7: acr-11 | B7: WBGene00000050 | C7: =npr_unprocessed!E7>0 -> TRUE | D7: =npr_unprocessed!F7>0 -> FALSE | E7: =npr_unprocessed!G7>0 -> FALSE | F7: =npr_unprocessed!H7>0 -> FALSE | G7: =npr_unprocessed!I7>0 -> FALSE | H7: =npr_unprocessed!J7>0 -> FALSE | I7: =npr_unprocessed!K7>0 -> FALSE | J7: =npr_unprocessed!L7>0 -> FALSE | ... EG7: =npr_unprocessed!EI7>0 -> FALSE
A8: acr-12 | B8: WBGene00000051 | C8: =npr_unprocessed!E8>0 -> FALSE | D8: =npr_unprocessed!F8>0 -> TRUE | E8: =npr_unprocessed!G8>0 -> FALSE | F8: =npr_unprocessed!H8>0 -> FALSE | G8: =npr_unprocessed!I8>0 -> FALSE | H8: =npr_unprocessed!J8>0 -> FALSE | I8: =npr_unprocessed!K8>0 -> FALSE | J8: =npr_unprocessed!L8>0 -> FALSE | ... EG8: =npr_unprocessed!EI8>0 -> TRUE
A9: acr-14 | B9: WBGene00000053 | C9: =npr_unprocessed!E9>0 -> FALSE | D9: =npr_unprocessed!F9>0 -> FALSE | E9: =npr_unprocessed!G9>0 -> FALSE | F9: =npr_unprocessed!H9>0 -> FALSE | G9: =npr_unprocessed!I9>0 -> FALSE | H9: =npr_unprocessed!J9>0 -> FALSE | I9: =npr_unprocessed!K9>0 -> FALSE | J9: =npr_unprocessed!L9>0 -> FALSE | ... EG9: =npr_unprocessed!EI9>0 -> TRUE
A10: acr-15 | B10: WBGene00000054 | C10: =npr_unprocessed!E10>0 -> FALSE | D10: =npr_unprocessed!F10>0 -> FALSE | E10: =npr_unprocessed!G10>0 -> FALSE | F10: =npr_unprocessed!H10>0 -> FALSE | G10: =npr_unprocessed!I10>0 -> FALSE | H10: =npr_unprocessed!J10>0 -> FALSE | I10: =npr_unprocessed!K10>0 -> FALSE | J10: =npr_unprocessed!L10>0 -> FALSE | ... EG10: =npr_unprocessed!EI10>0 -> FALSE
A11: acr-16 | B11: WBGene00000055 | C11: =npr_unprocessed!E11>0 -> FALSE | D11: =npr_unprocessed!F11>0 -> FALSE | E11: =npr_unprocessed!G11>0 -> FALSE | F11: =npr_unprocessed!H11>0 -> FALSE | G11: =npr_unprocessed!I11>0 -> FALSE | H11: =npr_unprocessed!J11>0 -> FALSE | I11: =npr_unprocessed!K11>0 -> FALSE | J11: =npr_unprocessed!L11>0 -> FALSE | ... EG11: =npr_unprocessed!EI11>0 -> FALSE
A12: acr-17 | B12: WBGene00000056 | C12: =npr_unprocessed!E12>0 -> FALSE | D12: =npr_unprocessed!F12>0 -> FALSE | E12: =npr_unprocessed!G12>0 -> TRUE | F12: =npr_unprocessed!H12>0 -> FALSE | G12: =npr_unprocessed!I12>0 -> FALSE | H12: =npr_unprocessed!J12>0 -> FALSE | I12: =npr_unprocessed!K12>0 -> FALSE | J12: =npr_unprocessed!L12>0 -> FALSE | ... EG12: =npr_unprocessed!EI12>0 -> FALSE
A13: acr-18 | B13: WBGene00000057 | C13: =npr_unprocessed!E13>0 -> FALSE | D13: =npr_unprocessed!F13>0 -> FALSE | E13: =npr_unprocessed!G13>0 -> FALSE | F13: =npr_unprocessed!H13>0 -> FALSE | G13: =npr_unprocessed!I13>0 -> FALSE | H13: =npr_unprocessed!J13>0 -> FALSE | I13: =npr_unprocessed!K13>0 -> FALSE | J13: =npr_unprocessed!L13>0 -> FALSE | ... EG13: =npr_unprocessed!EI13>0 -> FALSE
... A170: unc-63 | B170: WBGene00006797 | C170: =npr_unprocessed!E170>0 -> FALSE | D170: =npr_unprocessed!F170>0 -> FALSE | E170: =npr_unprocessed!G170>0 -> FALSE | F170: =npr_unprocessed!H170>0 -> FALSE | G170: =npr_unprocessed!I170>0 -> FALSE | H170: =npr_unprocessed!J170>0 -> FALSE | I170: =npr_unprocessed!K170>0 -> FALSE | J170: =npr_unprocessed!L170>0 -> TRUE | ... EG170: =npr_unprocessed!EI170>0 -> FALSE

Sheet npr
A1: gene_name | B1: X | C1: ADA | D1: ADE | E1: ADF | F1: ADL | G1: AFD | H1: AIA | I1: AIB | J1: AIM | K1: AIN | L1: AIY | M1: AIZ | N1: ALA | O1: ALM | P1: ALN | Q1: AQR | R1: AS | S1: ASEL | T1: ASER | U1: ASG | V1: ASH | W1: ASI | X1: ASJ | Y1: ASK | Z1: AUA | AA1: AVA | AB1: AVB | AC1: AVD | AD1: AVE | AE1: AVF | AF1: AVG | AG1: AVH | AH1: AVJ | AI1: AVK | AJ1: AVL | AK1: AVM | AL1: AWA | AM1: AWB | AN1: AWCL | AO1: AWCR | AP1: BAG | AQ1: BDU | AR1: CAN | AS1: CEP | AT1: DA | AU1: DA09 | AV1: DB | AW1: DB01 | AX1: DVA | AY1: DVB | AZ1: DVC | BA1: FLP | BB1: HSN | BC1: I1 | BD1: I2 | BE1: I3 | BF1: I4 | BG1: I5 | BH1: I6 | BI1: IL1 | BJ1: IL2D | BK1: IL2V | BL1: IL2L | BM1: IL2R | BN1: LUA | BO1: M1 | BP1: M2 | BQ1: M3 | BR1: M4 | BS1: M5 | BT1: MC | BU1: MI | BV1: NSM | BW1: OLL | BX1: OLQ | BY1: PDA | BZ1: PDB | CA1: PDE | CB1: PHA | CC1: PHB | CD1: PHC | CE1: PLM | CF1: PLN | CG1: PQR | CH1: PVC | CI1: PVD | CJ1: PVM | CK1: PVN | CL1: PVP | CM1: PVQ | CN1: PVR | CO1: PVT | CP1: PVW | CQ1: RIA | CR1: RIB | CS1: RIC | CT1: RID | CU1: RIF | CV1: RIG | CW1: RIH | CX1: RIM | CY1: RIP | CZ1: RIR | DA1: RIS | DB1: RIV | DC1: RMDD | DD1: RMDV | DE1: RMDL | DF1: RMDR | DG1: RMED | DH1: RMEV | DI1: RMEL | DJ1: RMER | DK1: RMF | DL1: RMG | DM1: RMH | DN1: SAA | DO1: SAB | DP1: SDQ | DQ1: SIA | DR1: SIB | DS1: SMB | DT1: SMD | DU1: URA | DV1: URB | DW1: URX | DX1: URY | DY1: VA | DZ1: VA12 | EA1: VB | EB1: VB01 | EC1: VB02 | ED1: VC | EE1: VC_4_5 | EF1: VD | EG1: DD
A2: acc-1 | B2: WBGene00010275 | C2: FALSE | D2: FALSE | E2: FALSE | F2: FALSE | G2: FALSE | H2: FALSE | I2: TRUE | J2: FALSE | K2: FALSE | L2: FALSE | M2: FALSE | N2: FALSE | O2: FALSE | P2: FALSE | Q2: FALSE | R2: FALSE | S2: FALSE | T2: FALSE | U2: FALSE | V2: FALSE | W2: FALSE | X2: FALSE | Y2: FALSE | Z2: FALSE | AA2: FALSE | AB2: FALSE | AC2: FALSE | AD2: FALSE | AE2: FALSE | AF2: FALSE | AG2: FALSE | AH2: FALSE | AI2: FALSE | AJ2: FALSE | AK2: FALSE | AL2: FALSE | AM2: FALSE | AN2: FALSE | AO2: FALSE | AP2: FALSE | AQ2: FALSE | AR2: FALSE | AS2: FALSE | AT2: TRUE | AU2: TRUE | AV2: TRUE | AW2: TRUE | AX2: FALSE | AY2: FALSE | AZ2: FALSE | BA2: FALSE | BB2: FALSE | BC2: FALSE | BD2: FALSE | BE2: FALSE | BF2: FALSE | BG2: FALSE | BH2: TRUE | BI2: FALSE | BJ2: FALSE | BK2: FALSE | BL2: FALSE | BM2: FALSE | BN2: FALSE | BO2: FALSE | BP2: FALSE | BQ2: TRUE | BR2: FALSE | BS2: FALSE | BT2: TRUE | BU2: TRUE | BV2: FALSE | BW2: FALSE | BX2: FALSE | BY2: FALSE | BZ2: FALSE | CA2: FALSE | CB2: FALSE | CC2: FALSE | CD2: FALSE | CE2: TRUE | CF2: FALSE | CG2: FALSE | CH2: FALSE | CI2: FALSE | CJ2: FALSE | CK2: FALSE | CL2: FALSE | CM2: FALSE | CN2: FALSE | CO2: FALSE | CP2: FALSE | CQ2: FALSE | CR2: FALSE | CS2: FALSE | CT2: FALSE | CU2: FALSE | CV2: FALSE | CW2: FALSE | CX2: FALSE | CY2: FALSE | CZ2: FALSE | DA2: FALSE | DB2: FALSE | DC2: TRUE | DD2: TRUE | DE2: TRUE | DF2: TRUE | DG2: FALSE | DH2: FALSE | DI2: FALSE | DJ2: FALSE | DK2: FALSE | DL2: FALSE | DM2: FALSE | DN2: TRUE | DO2: FALSE | DP2: FALSE | DQ2: FALSE | DR2: FALSE | DS2: FALSE | DT2: TRUE | DU2: FALSE | DV2: FALSE | DW2: FALSE | DX2: FALSE | DY2: FALSE | DZ2: FALSE | EA2: FALSE | EB2: FALSE | EC2: FALSE | ED2: FALSE | EE2: FALSE | EF2: FALSE | EG2: FALSE
A3: acc-2 | B3: WBGene00008280 | C3: FALSE | D3: FALSE | E3: FALSE | F3: FALSE | G3: FALSE | H3: FALSE | I3: FALSE | J3: TRUE | K3: FALSE | L3: FALSE | M3: TRUE | N3: FALSE | O3: FALSE | P3: FALSE | Q3: FALSE | R3: FALSE | S3: FALSE | T3: FALSE | U3: FALSE | V3: FALSE | W3: FALSE | X3: FALSE | Y3: FALSE | Z3: FALSE | AA3: FALSE | AB3: FALSE | AC3: FALSE | AD3: FALSE | AE3: FALSE | AF3: FALSE | AG3: FALSE | AH3: FALSE | AI3: FALSE | AJ3: FALSE | AK3: FALSE | AL3: FALSE | AM3: FALSE | AN3: FALSE | AO3: FALSE | AP3: FALSE | AQ3: FALSE | AR3: FALSE | AS3: FALSE | AT3: FALSE | AU3: FALSE | AV3: FALSE | AW3: FALSE | AX3: FALSE | AY3: FALSE | AZ3: FALSE | BA3: FALSE | BB3: FALSE | BC3: FALSE | BD3: FALSE | BE3: FALSE | BF3: FALSE | BG3: FALSE | BH3: FALSE | BI3: FALSE | BJ3: FALSE | BK3: FALSE | BL3: TRUE | BM3: TRUE | BN3: FALSE | BO3: FALSE | BP3: FALSE | BQ3: FALSE | BR3: FALSE | BS3: FALSE | BT3: FALSE | BU3: FALSE | BV3: FALSE | BW3: FALSE | BX3: FALSE | BY3: FALSE | BZ3: FALSE | CA3: FALSE | CB3: FALSE | CC3: FALSE | CD3: FALSE | CE3: FALSE | CF3: FALSE | CG3: FALSE | CH3: FALSE | CI3: FALSE | CJ3: FALSE | CK3: FALSE | CL3: FALSE | CM3: FALSE | CN3: FALSE | CO3: FALSE | CP3: FALSE | CQ3: TRUE | CR3: FALSE | CS3: FALSE | CT3: FALSE | CU3: FALSE | CV3: TRUE | CW3: FALSE | CX3: FALSE | CY3: FALSE | CZ3: FALSE | DA3: FALSE | DB3: FALSE | DC3: FALSE | DD3: FALSE | DE3: FALSE | DF3: FALSE | DG3: FALSE | DH3: FALSE | DI3: FALSE | DJ3: FALSE | DK3: FALSE | DL3: FALSE | DM3: FALSE | DN3: FALSE | DO3: FALSE | DP3: FALSE | DQ3: FALSE | DR3: FALSE | DS3: FALSE | DT3: FALSE | DU3: FALSE | DV3: FALSE | DW3: TRUE | DX3: FALSE | DY3: FALSE | DZ3: FALSE | EA3: FALSE | EB3: FALSE | EC3: FALSE | ED3: FALSE | EE3: FALSE | EF3: FALSE | EG3: FALSE
A4: acc-3 | B4: WBGene00018880 | C4: FALSE | D4: FALSE | E4: TRUE | F4: FALSE | G4: FALSE | H4: FALSE | I4: FALSE | J4: FALSE | K4: FALSE | L4: FALSE | M4: FALSE | N4: TRUE | O4: FALSE | P4: FALSE | Q4: FALSE | R4: FALSE | S4: FALSE | T4: FALSE | U4: FALSE | V4: FALSE | W4: FALSE | X4: FALSE | Y4: FALSE | Z4: FALSE | AA4: FALSE | AB4: FALSE | AC4: FALSE | AD4: FALSE | AE4: FALSE | AF4: FALSE | AG4: FALSE | AH4: FALSE | AI4: FALSE | AJ4: FALSE | AK4: FALSE | AL4: FALSE | AM4: FALSE | AN4: FALSE | AO4: FALSE | AP4: FALSE | AQ4: FALSE | AR4: FALSE | AS4: FALSE | AT4: FALSE | AU4: FALSE | AV4: FALSE | AW4: FALSE | AX4: FALSE | AY4: FALSE | AZ4: TRUE | BA4: FALSE | BB4: FALSE | BC4: FALSE | BD4: FALSE | BE4: FALSE | BF4: FALSE | BG4: FALSE | BH4: FALSE | BI4: FALSE | BJ4: FALSE | BK4: FALSE | BL4: FALSE | BM4: FALSE | BN4: FALSE | BO4: FALSE | BP4: FALSE | BQ4: FALSE | BR4: FALSE | BS4: FALSE | BT4: FALSE | BU4: FALSE | BV4: FALSE | BW4: FALSE | BX4: FALSE | BY4: FALSE | BZ4: FALSE | CA4: FALSE | CB4: FALSE | CC4: FALSE | CD4: FALSE | CE4: FALSE | CF4: FALSE | CG4: FALSE | CH4: FALSE | CI4: FALSE | CJ4: FALSE | CK4: FALSE | CL4: FALSE | CM4: FALSE | CN4: FALSE | CO4: FALSE | CP4: FALSE | CQ4: FALSE | CR4: FALSE | CS4: FALSE | CT4: FALSE | CU4: FALSE | CV4: FALSE | CW4: FALSE | CX4: TRUE | CY4: FALSE | CZ4: FALSE | DA4: FALSE | DB4: FALSE | DC4: FALSE | DD4: FALSE | DE4: FALSE | DF4: FALSE | DG4: TRUE | DH4: TRUE | DI4: FALSE | DJ4: FALSE | DK4: FALSE | DL4: FALSE | DM4: FALSE | DN4: FALSE | DO4: FALSE | DP4: FALSE | DQ4: FALSE | DR4: FALSE | DS4: FALSE | DT4: FALSE | DU4: FALSE | DV4: FALSE | DW4: FALSE | DX4: FALSE | DY4: FALSE | DZ4: FALSE | EA4: FALSE | EB4: FALSE | EC4: FALSE | ED4: FALSE | EE4: FALSE | EF4: FALSE | EG4: FALSE
A5: acc-4 | B5: WBGene00012099 | C5: FALSE | D5: FALSE | E5: FALSE | F5: FALSE | G5: FALSE | H5: TRUE | I5: FALSE | J5: FALSE | K5: FALSE | L5: FALSE | M5: FALSE | N5: FALSE | O5: FALSE | P5: FALSE | Q5: FALSE | R5: TRUE | S5: FALSE | T5: FALSE | U5: FALSE | V5: FALSE | W5: FALSE | X5: FALSE | Y5: FALSE | Z5: FALSE | AA5: TRUE | AB5: FALSE | AC5: TRUE | AD5: FALSE | AE5: FALSE | AF5: FALSE | AG5: FALSE | AH5: FALSE | AI5: FALSE | AJ5: FALSE | AK5: FALSE | AL5: FALSE | AM5: FALSE | AN5: FALSE | AO5: FALSE | AP5: FALSE | AQ5: FALSE | AR5: FALSE | AS5: FALSE | AT5: TRUE | AU5: TRUE | AV5: TRUE | AW5: TRUE | AX5: FALSE | AY5: FALSE | AZ5: FALSE | BA5: FALSE | BB5: TRUE | BC5: FALSE | BD5: FALSE | BE5: FALSE | BF5: FALSE | BG5: FALSE | BH5: FALSE | BI5: FALSE | BJ5: TRUE | BK5: TRUE | BL5: TRUE | BM5: TRUE | BN5: FALSE | BO5: TRUE | BP5: FALSE | BQ5: FALSE | BR5: TRUE | BS5: FALSE | BT5: FALSE | BU5: FALSE | BV5: FALSE | BW5: FALSE | BX5: FALSE | BY5: FALSE | BZ5: TRUE | CA5: FALSE | CB5: FALSE | CC5: FALSE | CD5: FALSE | CE5: FALSE | CF5: TRUE | CG5: FALSE | CH5: TRUE | CI5: FALSE | CJ5: FALSE | CK5: FALSE | CL5: FALSE | CM5: FALSE | CN5: FALSE | CO5: FALSE | CP5: FALSE | CQ5: FALSE | CR5: FALSE | CS5: FALSE | CT5: TRUE | CU5: TRUE | CV5: FALSE | CW5: TRUE | CX5: FALSE | CY5: TRUE | CZ5: FALSE | DA5: FALSE | DB5: FALSE | DC5: FALSE | DD5: FALSE | DE5: FALSE | DF5: FALSE | DG5: FALSE | DH5: FALSE | DI5: FALSE | DJ5: FALSE | DK5: FALSE | DL5: FALSE | DM5: FALSE | DN5: FALSE | DO5: TRUE | DP5: FALSE | DQ5: TRUE | DR5: TRUE | DS5: TRUE | DT5: FALSE | DU5: TRUE | DV5: TRUE | DW5: TRUE | DX5: FALSE | DY5: TRUE | DZ5: TRUE | EA5: TRUE | EB5: TRUE | EC5: TRUE | ED5: FALSE | EE5: FALSE | EF5: FALSE | EG5: FALSE
A6: acr-10 | B6: WBGene00000049 | C6: FALSE | D6: FALSE | E6: FALSE | F6: FALSE | G6: FALSE | H6: FALSE | I6: FALSE | J6: FALSE | K6: FALSE | L6: FALSE | M6: FALSE | N6: FALSE | O6: FALSE | P6: FALSE | Q6: FALSE | R6: FALSE | S6: FALSE | T6: FALSE | U6: FALSE | V6: FALSE | W6: FALSE | X6: FALSE | Y6: FALSE | Z6: FALSE | AA6: FALSE | AB6: FALSE | AC6: FALSE | AD6: FALSE | AE6: FALSE | AF6: FALSE | AG6: FALSE | AH6: FALSE | AI6: FALSE | AJ6: FALSE | AK6: FALSE | AL6: FALSE | AM6: FALSE | AN6: FALSE | AO6: FALSE | AP6: FALSE | AQ6: FALSE | AR6: FALSE | AS6: FALSE | AT6: FALSE | AU6: FALSE | AV6: FALSE | AW6: FALSE | AX6: FALSE | AY6: FALSE | AZ6: FALSE | BA6: FALSE | BB6: FALSE | BC6: FALSE | BD6: FALSE | BE6: FALSE | BF6: FALSE | BG6: FALSE | BH6: FALSE | BI6: FALSE | BJ6: FALSE | BK6: FALSE | BL6: FALSE | BM6: FALSE | BN6: FALSE | BO6: FALSE | BP6: FALSE | BQ6: FALSE | BR6: FALSE | BS6: FALSE | BT6: FALSE | BU6: FALSE | BV6: FALSE | BW6: FALSE | BX6: FALSE | BY6: FALSE | BZ6: FALSE | CA6: FALSE | CB6: FALSE | CC6: FALSE | CD6: FALSE | CE6: FALSE | CF6: FALSE | CG6: FALSE | CH6: FALSE | CI6: FALSE | CJ6: FALSE | CK6: FALSE | CL6: FALSE | CM6: FALSE | CN6: FALSE | CO6: FALSE | CP6: FALSE | CQ6: FALSE | CR6: FALSE | CS6: FALSE | CT6: FALSE | CU6: FALSE | CV6: FALSE | CW6: FALSE | CX6: FALSE | CY6: FALSE | CZ6: FALSE | DA6: FALSE | DB6: FALSE | DC6: FALSE | DD6: FALSE | DE6: FALSE | DF6: FALSE | DG6: FALSE | DH6: FALSE | DI6: FALSE | DJ6: FALSE | DK6: FALSE | DL6: FALSE | DM6: FALSE | DN6: FALSE | DO6: FALSE | DP6: FALSE | DQ6: FALSE | DR6: FALSE | DS6: FALSE | DT6: FALSE | DU6: FALSE | DV6: FALSE | DW6: FALSE | DX6: FALSE | DY6: FALSE | DZ6: FALSE | EA6: FALSE | EB6: FALSE | EC6: FALSE | ED6: FALSE | EE6: FALSE | EF6: FALSE | EG6: FALSE
A7: acr-11 | B7: WBGene00000050 | C7: TRUE | D7: FALSE | E7: FALSE | F7: FALSE | G7: FALSE | H7: FALSE | I7: FALSE | J7: FALSE | K7: FALSE | L7: FALSE | M7: FALSE | N7: FALSE | O7: FALSE | P7: FALSE | Q7: FALSE | R7: FALSE | S7: FALSE | T7: FALSE | U7: FALSE | V7: FALSE | W7: FALSE | X7: FALSE | Y7: FALSE | Z7: FALSE | AA7: FALSE | AB7: FALSE | AC7: FALSE | AD7: FALSE | AE7: FALSE | AF7: FALSE | AG7: FALSE | AH7: FALSE | AI7: FALSE | AJ7: FALSE | AK7: FALSE | AL7: FALSE | AM7: FALSE | AN7: FALSE | AO7: FALSE | AP7: FALSE | AQ7: FALSE | AR7: FALSE | AS7: FALSE | AT7: FALSE | AU7: FALSE | AV7: FALSE | AW7: FALSE | AX7: FALSE | AY7: FALSE | AZ7: FALSE | BA7: FALSE | BB7: FALSE | BC7: FALSE | BD7: FALSE | BE7: FALSE | BF7: FALSE | BG7: FALSE | BH7: FALSE | BI7: FALSE | BJ7: FALSE | BK7: FALSE | BL7: FALSE | BM7: FALSE | BN7: FALSE | BO7: FALSE | BP7: FALSE | BQ7: FALSE | BR7: FALSE | BS7: FALSE | BT7: FALSE | BU7: FALSE | BV7: FALSE | BW7: FALSE | BX7: FALSE | BY7: FALSE | BZ7: FALSE | CA7: FALSE | CB7: FALSE | CC7: FALSE | CD7: FALSE | CE7: FALSE | CF7: FALSE | CG7: FALSE | CH7: FALSE | CI7: FALSE | CJ7: FALSE | CK7: FALSE | CL7: FALSE | CM7: FALSE | CN7: FALSE | CO7: FALSE | CP7: FALSE | CQ7: FALSE | CR7: FALSE | CS7: FALSE | CT7: FALSE | CU7: FALSE | CV7: FALSE | CW7: FALSE | CX7: FALSE | CY7: FALSE | CZ7: FALSE | DA7: FALSE | DB7: FALSE | DC7: FALSE | DD7: FALSE | DE7: FALSE | DF7: FALSE | DG7: FALSE | DH7: FALSE | DI7: FALSE | DJ7: FALSE | DK7: FALSE | DL7: FALSE | DM7: FALSE | DN7: FALSE | DO7: FALSE | DP7: FALSE | DQ7: FALSE | DR7: FALSE | DS7: FALSE | DT7: FALSE | DU7: FALSE | DV7: TRUE | DW7: FALSE | DX7: FALSE | DY7: FALSE | DZ7: FALSE | EA7: FALSE | EB7: FALSE | EC7: FALSE | ED7: FALSE | EE7: FALSE | EF7: FALSE | EG7: FALSE
A8: acr-12 | B8: WBGene00000051 | C8: FALSE | D8: TRUE | E8: FALSE | F8: FALSE | G8: FALSE | H8: FALSE | I8: FALSE | J8: FALSE | K8: FALSE | L8: TRUE | M8: TRUE | N8: FALSE | O8: TRUE | P8: FALSE | Q8: FALSE | R8: TRUE | S8: FALSE | T8: FALSE | U8: FALSE | V8: FALSE | W8: FALSE | X8: FALSE | Y8: FALSE | Z8: TRUE | AA8: FALSE | AB8: TRUE | AC8: TRUE | AD8: FALSE | AE8: FALSE | AF8: TRUE | AG8: TRUE | AH8: TRUE | AI8: TRUE | AJ8: TRUE | AK8: TRUE | AL8: FALSE | AM8: FALSE | AN8: FALSE | AO8: FALSE | AP8: FALSE | AQ8: FALSE | AR8: FALSE | AS8: FALSE | AT8: TRUE | AU8: TRUE | AV8: TRUE | AW8: TRUE | AX8: FALSE | AY8: TRUE | AZ8: FALSE | BA8: FALSE | BB8: TRUE | BC8: TRUE | BD8: FALSE | BE8: FALSE | BF8: TRUE | BG8: TRUE | BH8: FALSE | BI8: TRUE | BJ8: TRUE | BK8: TRUE | BL8: TRUE | BM8: TRUE | BN8: FALSE | BO8: FALSE | BP8: TRUE | BQ8: FALSE | BR8: TRUE | BS8: TRUE | BT8: FALSE | BU8: FALSE | BV8: TRUE | BW8: TRUE | BX8: FALSE | BY8: TRUE | BZ8: TRUE | CA8: TRUE | CB8: FALSE | CC8: FALSE | CD8: FALSE | CE8: TRUE | CF8: TRUE | CG8: FALSE | CH8: TRUE | CI8: FALSE | CJ8: TRUE | CK8: FALSE | CL8: FALSE | CM8: FALSE | CN8: TRUE | CO8: TRUE | CP8: TRUE | CQ8: FALSE | CR8: FALSE | CS8: FALSE | CT8: TRUE | CU8: FALSE | CV8: TRUE | CW8: FALSE | CX8: TRUE | CY8: FALSE | CZ8: FALSE | DA8: TRUE | DB8: FALSE | DC8: TRUE | DD8: TRUE | DE8: TRUE | DF8: TRUE | DG8: FALSE | DH8: FALSE | DI8: FALSE | DJ8: FALSE | DK8: TRUE | DL8: FALSE | DM8: FALSE | DN8: TRUE | DO8: TRUE | DP8: FALSE | DQ8: FALSE | DR8: TRUE | DS8: TRUE | DT8: TRUE | DU8: TRUE | DV8: FALSE | DW8: FALSE | DX8: FALSE | DY8: TRUE | DZ8: TRUE | EA8: TRUE | EB8: TRUE | EC8: TRUE | ED8: TRUE | EE8: FALSE | EF8: TRUE | EG8: TRUE
A9: acr-14 | B9: WBGene00000053 | C9: FALSE | D9: FALSE | E9: FALSE | F9: FALSE | G9: FALSE | H9: FALSE | I9: FALSE | J9: FALSE | K9: FALSE | L9: FALSE | M9: FALSE | N9: FALSE | O9: FALSE | P9: FALSE | Q9: FALSE | R9: TRUE | S9: FALSE | T9: FALSE | U9: FALSE | V9: FALSE | W9: FALSE | X9: FALSE | Y9: FALSE | Z9: FALSE | AA9: TRUE | AB9: FALSE | AC9: TRUE | AD9: TRUE | AE9: FALSE | AF9: FALSE | AG9: FALSE | AH9: TRUE | AI9: FALSE | AJ9: FALSE | AK9: FALSE | AL9: FALSE | AM9: FALSE | AN9: FALSE | AO9: FALSE | AP9: FALSE | AQ9: FALSE | AR9: FALSE | AS9: FALSE | AT9: TRUE | AU9: TRUE | AV9: FALSE | AW9: FALSE | AX9: FALSE | AY9: FALSE | AZ9: FALSE | BA9: FALSE | BB9: FALSE | BC9: FALSE | BD9: FALSE | BE9: FALSE | BF9: FALSE | BG9: FALSE | BH9: FALSE | BI9: FALSE | BJ9: FALSE | BK9: FALSE | BL9: FALSE | BM9: FALSE | BN9: FALSE | BO9: FALSE | BP9: TRUE | BQ9: FALSE | BR9: FALSE | BS9: FALSE | BT9: FALSE | BU9: FALSE | BV9: FALSE | BW9: FALSE | BX9: FALSE | BY9: TRUE | BZ9: TRUE | CA9: FALSE | CB9: FALSE | CC9: FALSE | CD9: FALSE | CE9: FALSE | CF9: FALSE | CG9: FALSE | CH9: FALSE | CI9: FALSE | CJ9: FALSE | CK9: TRUE | CL9: TRUE | CM9: FALSE | CN9: FALSE | CO9: FALSE | CP9: FALSE | CQ9: FALSE | CR9: FALSE | CS9: FALSE | CT9: FALSE | CU9: TRUE | CV9: FALSE | CW9: FALSE | CX9: FALSE | CY9: FALSE | CZ9: FALSE | DA9: FALSE | DB9: FALSE | DC9: FALSE | DD9: FALSE | DE9: FALSE | DF9: FALSE | DG9: FALSE | DH9: FALSE | DI9: FALSE | DJ9: FALSE | DK9: FALSE | DL9: FALSE | DM9: FALSE | DN9: FALSE | DO9: TRUE | DP9: FALSE | DQ9: FALSE | DR9: FALSE | DS9: FALSE | DT9: FALSE | DU9: FALSE | DV9: FALSE | DW9: FALSE | DX9: FALSE | DY9: TRUE | DZ9: TRUE | EA9: FALSE | EB9: FALSE | EC9: FALSE | ED9: FALSE | EE9: FALSE | EF9: TRUE | EG9: TRUE
A10: acr-15 | B10: WBGene00000054 | C10: FALSE | D10: FALSE | E10: FALSE | F10: FALSE | G10: FALSE | H10: FALSE | I10: FALSE | J10: FALSE | K10: FALSE | L10: FALSE | M10: FALSE | N10: FALSE | O10: FALSE | P10: FALSE | Q10: FALSE | R10: FALSE | S10: FALSE | T10: FALSE | U10: FALSE | V10: FALSE | W10: FALSE | X10: FALSE | Y10: FALSE | Z10: FALSE | AA10: TRUE | AB10: TRUE | AC10: FALSE | AD10: FALSE | AE10: FALSE | AF10: TRUE | AG10: FALSE | AH10: FALSE | AI10: FALSE | AJ10: FALSE | AK10: FALSE | AL10: FALSE | AM10: FALSE | AN10: FALSE | AO10: FALSE | AP10: FALSE | AQ10: FALSE | AR10: FALSE | AS10: FALSE | AT10: FALSE | AU10: FALSE | AV10: TRUE | AW10: FALSE | AX10: FALSE | AY10: FALSE | AZ10: FALSE | BA10: FALSE | BB10: FALSE | BC10: FALSE | BD10: FALSE | BE10: FALSE | BF10: FALSE | BG10: TRUE | BH10: FALSE | BI10: FALSE | BJ10: FALSE | BK10: FALSE | BL10: FALSE | BM10: FALSE | BN10: FALSE | BO10: FALSE | BP10: FALSE | BQ10: TRUE | BR10: FALSE | BS10: FALSE | BT10: FALSE | BU10: FALSE | BV10: FALSE | BW10: FALSE | BX10: FALSE | BY10: FALSE | BZ10: TRUE | CA10: FALSE | CB10: FALSE | CC10: FALSE | CD10: FALSE | CE10: FALSE | CF10: FALSE | CG10: FALSE | CH10: FALSE | CI10: FALSE | CJ10: FALSE | CK10: FALSE | CL10: FALSE | CM10: FALSE | CN10: FALSE | CO10: FALSE | CP10: FALSE | CQ10: FALSE | CR10: FALSE | CS10: FALSE | CT10: FALSE | CU10: FALSE | CV10: FALSE | CW10: FALSE | CX10: FALSE | CY10: TRUE | CZ10: FALSE | DA10: FALSE | DB10: FALSE | DC10: FALSE | DD10: FALSE | DE10: FALSE | DF10: FALSE | DG10: FALSE | DH10: FALSE | DI10: FALSE | DJ10: FALSE | DK10: FALSE | DL10: FALSE | DM10: FALSE | DN10: FALSE | DO10: FALSE | DP10: FALSE | DQ10: FALSE | DR10: FALSE | DS10: FALSE | DT10: FALSE | DU10: FALSE | DV10: FALSE | DW10: FALSE | DX10: FALSE | DY10: FALSE | DZ10: TRUE | EA10: FALSE | EB10: FALSE | EC10: FALSE | ED10: FALSE | EE10: FALSE | EF10: FALSE | EG10: FALSE
A11: acr-16 | B11: WBGene00000055 | C11: FALSE | D11: FALSE | E11: FALSE | F11: FALSE | G11: FALSE | H11: FALSE | I11: FALSE | J11: FALSE | K11: FALSE | L11: FALSE | M11: FALSE | N11: FALSE | O11: FALSE | P11: FALSE | Q11: FALSE | R11: FALSE | S11: FALSE | T11: FALSE | U11: FALSE | V11: FALSE | W11: FALSE | X11: FALSE | Y11: FALSE | Z11: FALSE | AA11: TRUE | AB11: TRUE | AC11: FALSE | AD11: FALSE | AE11: FALSE | AF11: FALSE | AG11: FALSE | AH11: FALSE | AI11: FALSE | AJ11: FALSE | AK11: FALSE | AL11: FALSE | AM11: FALSE | AN11: FALSE | AO11: FALSE | AP11: FALSE | AQ11: FALSE | AR11: FALSE | AS11: FALSE | AT11: FALSE | AU11: FALSE | AV11: TRUE | AW11: FALSE | AX11: FALSE | AY11: FALSE | AZ11: FALSE | BA11: FALSE | BB11: FALSE | BC11: FALSE | BD11: FALSE | BE11: FALSE | BF11: FALSE | BG11: FALSE | BH11: FALSE | BI11: FALSE | BJ11: FALSE | BK11: FALSE | BL11: FALSE | BM11: FALSE | BN11: FALSE | BO11: FALSE | BP11: FALSE | BQ11: FALSE | BR11: TRUE | BS11: FALSE | BT11: FALSE | BU11: FALSE | BV11: FALSE | BW11: FALSE | BX11: FALSE | BY11: FALSE | BZ11: FALSE | CA11: FALSE | CB11: FALSE | CC11: FALSE | CD11: FALSE | CE11: FALSE | CF11: FALSE | CG11: FALSE | CH11: FALSE | CI11: FALSE | CJ11: FALSE | CK11: FALSE | CL11: FALSE | CM11: FALSE | CN11: TRUE | CO11: FALSE | CP11: FALSE | CQ11: FALSE | CR11: TRUE | CS11: FALSE | CT11: FALSE | CU11: FALSE | CV11: FALSE | CW11: FALSE | CX11: FALSE | CY11: FALSE | CZ11: FALSE | DA11: FALSE | DB11: FALSE | DC11: FALSE | DD11: FALSE | DE11: FALSE | DF11: FALSE | DG11: FALSE | DH11: FALSE | DI11: FALSE | DJ11: FALSE | DK11: FALSE | DL11: FALSE | DM11: FALSE | DN11: FALSE | DO11: FALSE | DP11: FALSE | DQ11: FALSE | DR11: FALSE | DS11: FALSE | DT11: TRUE | DU11: FALSE | DV11: FALSE | DW11: FALSE | DX11: FALSE | DY11: FALSE | DZ11: FALSE | EA11: FALSE | EB11: FALSE | EC11: FALSE | ED11: FALSE | EE11: FALSE | EF11: FALSE | EG11: FALSE
A12: acr-17 | B12: WBGene00000056 | C12: FALSE | D12: FALSE | E12: TRUE | F12: FALSE | G12: FALSE | H12: FALSE | I12: FALSE | J12: FALSE | K12: FALSE | L12: FALSE | M12: FALSE | N12: FALSE | O12: FALSE | P12: FALSE | Q12: FALSE | R12: FALSE | S12: FALSE | T12: FALSE | U12: TRUE | V12: FALSE | W12: FALSE | X12: FALSE | Y12: FALSE | Z12: FALSE | AA12: FALSE | AB12: FALSE | AC12: FALSE | AD12: FALSE | AE12: FALSE | AF12: FALSE | AG12: FALSE | AH12: FALSE | AI12: FALSE | AJ12: FALSE | AK12: FALSE | AL12: FALSE | AM12: FALSE | AN12: FALSE | AO12: FALSE | AP12: FALSE | AQ12: FALSE | AR12: FALSE | AS12: FALSE | AT12: TRUE | AU12: FALSE | AV12: TRUE | AW12: FALSE | AX12: FALSE | AY12: TRUE | AZ12: FALSE | BA12: FALSE | BB12: TRUE | BC12: FALSE | BD12: FALSE | BE12: FALSE | BF12: FALSE | BG12: FALSE | BH12: FALSE | BI12: FALSE | BJ12: FALSE | BK12: FALSE | BL12: FALSE | BM12: FALSE | BN12: FALSE | BO12: TRUE | BP12: FALSE | BQ12: TRUE | BR12: FALSE | BS12: FALSE | BT12: FALSE | BU12: TRUE | BV12: FALSE | BW12: FALSE | BX12: FALSE | BY12: FALSE | BZ12: FALSE | CA12: FALSE | CB12: FALSE | CC12: FALSE | CD12: FALSE | CE12: FALSE | CF12: FALSE | CG12: FALSE | CH12: FALSE | CI12: TRUE | CJ12: FALSE | CK12: FALSE | CL12: FALSE | CM12: FALSE | CN12: FALSE | CO12: FALSE | CP12: FALSE | CQ12: FALSE | CR12: FALSE | CS12: FALSE | CT12: FALSE | CU12: FALSE | CV12: TRUE | CW12: TRUE | CX12: FALSE | CY12: TRUE | CZ12: FALSE | DA12: FALSE | DB12: FALSE | DC12: FALSE | DD12: FALSE | DE12: FALSE | DF12: FALSE | DG12: FALSE | DH12: FALSE | DI12: FALSE | DJ12: FALSE | DK12: FALSE | DL12: FALSE | DM12: FALSE | DN12: FALSE | DO12: FALSE | DP12: FALSE | DQ12: FALSE | DR12: FALSE | DS12: FALSE | DT12: FALSE | DU12: FALSE | DV12: FALSE | DW12: FALSE | DX12: FALSE | DY12: FALSE | DZ12: FALSE | EA12: FALSE | EB12: FALSE | EC12: FALSE | ED12: FALSE | EE12: FALSE | EF12: FALSE | EG12: FALSE
A13: acr-18 | B13: WBGene00000057 | C13: FALSE | D13: FALSE | E13: FALSE | F13: FALSE | G13: FALSE | H13: FALSE | I13: FALSE | J13: FALSE | K13: FALSE | L13: FALSE | M13: FALSE | N13: FALSE | O13: FALSE | P13: FALSE | Q13: FALSE | R13: FALSE | S13: FALSE | T13: FALSE | U13: FALSE | V13: FALSE | W13: FALSE | X13: FALSE | Y13: FALSE | Z13: FALSE | AA13: TRUE | AB13: FALSE | AC13: FALSE | AD13: TRUE | AE13: FALSE | AF13: FALSE | AG13: FALSE | AH13: FALSE | AI13: FALSE | AJ13: FALSE | AK13: FALSE | AL13: FALSE | AM13: FALSE | AN13: FALSE | AO13: FALSE | AP13: FALSE | AQ13: FALSE | AR13: FALSE | AS13: FALSE | AT13: FALSE | AU13: TRUE | AV13: FALSE | AW13: FALSE | AX13: TRUE | AY13: FALSE | AZ13: FALSE | BA13: FALSE | BB13: FALSE | BC13: FALSE | BD13: FALSE | BE13: FALSE | BF13: FALSE | BG13: FALSE | BH13: FALSE | BI13: FALSE | BJ13: FALSE | BK13: FALSE | BL13: FALSE | BM13: FALSE | BN13: FALSE | BO13: TRUE | BP13: FALSE | BQ13: FALSE | BR13: FALSE | BS13: FALSE | BT13: FALSE | BU13: FALSE | BV13: FALSE | BW13: FALSE | BX13: FALSE | BY13: FALSE | BZ13: TRUE | CA13: FALSE | CB13: FALSE | CC13: FALSE | CD13: FALSE | CE13: FALSE | CF13: FALSE | CG13: FALSE | CH13: FALSE | CI13: FALSE | CJ13: FALSE | CK13: FALSE | CL13: FALSE | CM13: FALSE | CN13: FALSE | CO13: FALSE | CP13: FALSE | CQ13: FALSE | CR13: FALSE | CS13: FALSE | CT13: FALSE | CU13: FALSE | CV13: FALSE | CW13: FALSE | CX13: FALSE | CY13: FALSE | CZ13: FALSE | DA13: FALSE | DB13: FALSE | DC13: FALSE | DD13: FALSE | DE13: FALSE | DF13: FALSE | DG13: FALSE | DH13: FALSE | DI13: FALSE | DJ13: FALSE | DK13: FALSE | DL13: FALSE | DM13: FALSE | DN13: FALSE | DO13: FALSE | DP13: FALSE | DQ13: TRUE | DR13: FALSE | DS13: FALSE | DT13: TRUE | DU13: TRUE | DV13: FALSE | DW13: FALSE | DX13: FALSE | DY13: FALSE | DZ13: FALSE | EA13: FALSE | EB13: TRUE | EC13: FALSE | ED13: FALSE | EE13: FALSE | EF13: FALSE | EG13: FALSE
... A170: unc-63 | B170: WBGene00006797 | C170: FALSE | D170: FALSE | E170: FALSE | F170: FALSE | G170: FALSE | H170: FALSE | I170: FALSE | J170: TRUE | K170: FALSE | L170: FALSE | M170: TRUE | N170: FALSE | O170: TRUE | P170: FALSE | Q170: FALSE | R170: TRUE | S170: FALSE | T170: FALSE | U170: FALSE | V170: FALSE | W170: FALSE | X170: FALSE | Y170: FALSE | Z170: FALSE | AA170: FALSE | AB170: FALSE | AC170: TRUE | AD170: FALSE | AE170: FALSE | AF170: TRUE | AG170: FALSE | AH170: FALSE | AI170: FALSE | AJ170: FALSE | AK170: TRUE | AL170: FALSE | AM170: FALSE | AN170: FALSE | AO170: FALSE | AP170: FALSE | AQ170: FALSE | AR170: FALSE | AS170: FALSE | AT170: TRUE | AU170: TRUE | AV170: TRUE | AW170: TRUE | AX170: FALSE | AY170: TRUE | AZ170: FALSE | BA170: FALSE | BB170: TRUE | BC170: TRUE | BD170: FALSE | BE170: FALSE | BF170: TRUE | BG170: TRUE | BH170: FALSE | BI170: TRUE | BJ170: TRUE | BK170: TRUE | BL170: TRUE | BM170: TRUE | BN170: FALSE | BO170: FALSE | BP170: TRUE | BQ170: TRUE | BR170: FALSE | BS170: FALSE | BT170: FALSE | BU170: TRUE | BV170: TRUE | BW170: FALSE | BX170: FALSE | BY170: TRUE | BZ170: TRUE | CA170: TRUE | CB170: FALSE | CC170: FALSE | CD170: FALSE | CE170: TRUE | CF170: FALSE | CG170: FALSE | CH170: TRUE | CI170: FALSE | CJ170: TRUE | CK170: FALSE | CL170: FALSE | CM170: FALSE | CN170: TRUE | CO170: FALSE | CP170: TRUE | CQ170: FALSE | CR170: FALSE | CS170: FALSE | CT170: FALSE | CU170: FALSE | CV170: FALSE | CW170: FALSE | CX170: FALSE | CY170: FALSE | CZ170: FALSE | DA170: FALSE | DB170: FALSE | DC170: FALSE | DD170: FALSE | DE170: FALSE | DF170: FALSE | DG170: FALSE | DH170: FALSE | DI170: FALSE | DJ170: FALSE | DK170: FALSE | DL170: FALSE | DM170: FALSE | DN170: FALSE | DO170: FALSE | DP170: FALSE | DQ170: FALSE | DR170: FALSE | DS170: TRUE | DT170: TRUE | DU170: TRUE | DV170: TRUE | DW170: FALSE | DX170: FALSE | DY170: TRUE | DZ170: TRUE | EA170: TRUE | EB170: TRUE | EC170: TRUE | ED170: FALSE | EE170: FALSE | EF170: FALSE | EG170: FALSE

Sheet Sheet2
A1: acc-1
A2: acc-2
A3: acc-3
A4: acc-4
A5: acr-10
A6: acr-11
A7: acr-12
A8: acr-13 (lev-8)
A9: acr-14
A10: acr-15
A11: acr-16
A12: acr-17
... A199: unc-63 (aka lev-7 and tmr-3)

Sheet ligmap
A1: Homolog/ Ortholog | B1: gene | E1: Sequence name | F1: Type | G1: ligand
A2: NEUROTRANSMITTER RECEPTORS
A3: SEROTONIN (5HT)
A4: Receptors
A5: 5-HT2 | B5: ser-1 | C5: (5-HTCeL, | D5: 5-HTCeS) | E5: F59C12.2 | F5: G protein-coupled receptor (GPCR) (Gαq); 7-transmembrane (7TM); coupled to Ca++ signaling | G5: Serotonin | H5: (a-methyl 5-HT for SER-1)
A6: 5-HT1 | B6: ser-4, | C6: (cer-1, | D6: 5HT-Ce) | E6: Y22D7AR.13 | F6: 7TM GPCR (Gαi/o); attenuates adenylyl cyclase activity | G6: Serotonin
A7: 5-HT6 | B7: ser-5 | E7: F16D3.7 | F7: 7TM GPCR; independent of adenylyl cyclase activity | G7: Serotonin
A8: 5-HT7 | B8: ser-7 | E8: C09B7.1 | F8: 7TM GPCR (Gαs); activates adenylyl cyclase activity | G8: Serotonin
A9: ? | B9: mod-1 | E9: K06C4.6 | F9: 5-HT-gated chloride channel | G9: Serotonin
B10: lgc-50 | E10: T20B12.9 | F10: Ligand-gated ion channel (mod-1 group)
A11: Homolog/Ortholog | B11: C. | C11: elegans | D11: gene | E11: Sequence name | F11: Type | G11: Ligand
A12: DOPAMINE (DA)
A13: Receptors
A14: D1-like | B14: dop-1 | E14: F15A8.5 | F14: 7TM GPCR (Gαs) | G14: Dopamine
A15: D2-like | B15: dop-2 | C15: (dop-2L) | E15: K09G1.4 | F15: 7TM GPCR (Gαi/o) | G15: Dopamine
A16: D2-like | B16: dop-3 | E16: T14E8.3 | F16: 7TM GPCR | G16: Dopamine
A17: Human TAR vs D1-like | B17: dop-4 | E17: C52B11.3 | F17: 7TM GPCR (Gα?) | G17: Dopamine
A18: Homolog of human melatonin type 1b receptors, and more generally of mammalian dopamine and serotonin (5-HT) receptors | B18: dop-5 | E18: T02E9.3 | F18: 7TM GPCR (Gα?) | G18: Dopamine? Serotonin?
A19: D2 or D3 dopamine receptors (mammalian homolog) | B19: dop-6 | E19: C24A8.1 | F19: 7TM GPCR (Gα?) | G19: Dopamine
A20: Ligand unspecified
B21: C24A8.6 | E21: C24A8.6 | F21: GPCR for small molecule neurotransmitters. 7TM rhodopsin family. Closest to C24A8.1 in phylogenetic tree | G21: ?
A22: Homolog/ Ortholog | B22: C. | C22: elegans | D22: gene | E22: Sequence name | F22: Type | G22: Ligand
A23: OCTOPAMINE (OA)
A24: Receptors
B25: octr-1 | E25: F14D12.6 | F25: 7TM GPCR (Gαs?) | G25: Octopamine
A26: 5HT4 | B26: ser-3 | E26: K02F2.6 | F26: 7TM GPCR (Gαq/Gαs?) | G26: Octopamine/serotonin?
B27: ser-6 | E27: Y54G2A.35 | F27: 7TM GPCR (Gαq) | G27: Octopamine
A28: Homolog/ Ortholog | B28: C. | C28: elegans | D28: gene | E28: Sequence name | F28: Type | G28: Ligand
A29: TYRAMINE (TA)
A30: Receptors
B31: ser-2 | E31: C02D4.2 | F31: 7TM GPCR (Gαi/o) | G31: Tyramine
A32: 5HT5 | B32: tyra-2 | E32: F01E11.5 | F32: 7TM GPCR (Gαi/o vs Gα?) | G32: Tyramine
B33: tyra-3 | E33: M03F4.3 | F33: 7TM GPCR (Gαq); independent of adenylyl cyclase activity | G33: Tyramine Octopamine
B34: lgc-55 | E34: Y113G7A.5 | F34: Ligand-gated ion (chloride) channel | G34: Tyramine?
A35: Homolog/ Ortholog | B35: C. | C35: elegans | D35: gene | E35: Sequence name | F35: Type | G35: Ligand
A36: TRACE AMINES
A37: Candidate GPCRs predicted to bind either small-molecule neurotransmitters (trace amine-associated (TAA) receptors) or neuropeptides
B38: F59D12.1 | E38: F59D12.1 | F38: GPCR. 7TM rhodopsin family. GPCR for small molecule neurotransmitters. Closest to T02E9.3 in phylogenetic tree. | G38: Melatonin?
B39: T21B4.4 | E39: T21B4.4 | F39: GPCR. 7TM rhodopsin family. GPCR for small molecule neurotransmitters. Closest to F42D1.3 in phylogenetic tree. Serpentine receptor class sx (Srsx) | G39: ?
A40: Homolog/ Ortholog | B40: C. | C40: elegans | D40: gene | E40: Sequence name | F40: Type | G40: Ligand
...
